Workbook

Sheet start
A25: content: S. Privett, M. Mergili; design: M. Mergili - © 2005 Grootbos Nature Reserve
B30: directory: | C30: D:\ResearchProjects\GrootbosVegetation\SpatialData\Ecosystems | G30: directory: | H30: D:\ResearchProjects\GrootbosVegetation\VegetationAnalysis\Tools\TABWIN

Sheet flora (2)
A1: 09.11. 2004 | B1: scientific name | C1: family | D1: Common Name | E1: genus | F1: species | G1: taxon | H1: life form | I1: LF1 | J1: LF2 | K1: LF3 | L1: LF4 | M1: LF5 | N1: LF6 | O1: LF_GandP | P1: LF_GandP2 | Q1: status (red data) | R1: Date | S1: to collect | T1: collected | U1: DN | V1: LS | W1: SP | X1: TM | Y1: MW | Z1: AM | AA1: WL | AB1: RP
A2: 1 | B2: =E2&" "&F2 -> Agapanthus africanus | C2: Agapanthaceae | D2: bloulelie | E2: Agapanthus | F2: africanus | G2: Agap afr | H2: GEOL BLS | I2: 4 | J2: 6 | K2: 5 | L2: 2 | M2: 1 | N2: 1 | O2: Geophyte | P2: perennial | R2: 35612 | S2: X | U2: 1
A3: 2 | B3: =E3&" "&F3 -> Carpanthea pomeridiana | C3: Aizoaceae | D3: vetkousie | E3: Carpanthea | F3: pomeridiana | G3: Carp pom | H3: ANNL BLF | I3: 6 | J3: 6 | K3: 3 | L3: 1 | M3: 4 | N3: 3 | O3: herb | P3: annual | R3: 36069 | T3: 1 | U3: 1
A4: 3 | B4: =E4&" "&F4 -> Carpobrotus acinaciformis | C4: Aizoaceae | D4: hottentot fig, sour fig, suurvy | E4: Carpobrotus | F4: acinaciformis | G4: Carp aci | H4: PERL BLF | I4: 3 | J4: 6 | K4: 3 | L4: 2 | M4: 3 | N4: 3 | O4: Succulent | P4: perennial | R4: 35612 | T4: 1 | U4: 1 | V4: 1 | W4: 1 | X4: 1 | AB4: 1
A5: 4 | B5: =E5&" "&F5 -> Carpobrotus edulis | C5: Aizoaceae | D5: hottentot fig, sour fig, suurvy | E5: Carpobrotus | F5: edulis | G5: Carp edu | H5: PERL BLF | I5: 3 | J5: 6 | K5: 3 | L5: 2 | M5: 3 | N5: 3 | O5: Succulent | P5: perennial | R5: 35612 | T5: 1 | U5: 1
A6: 5 | B6: =E6&" "&F6 -> Dorotheanthus bellidiformis | C6: Aizoaceae | D6: livingstone daisy, bokbaaivygie | E6: Dorotheanthus | F6: bellidiformis | G6: Doro bel | H6: ANNL BLF | I6: 6 | J6: 6 | K6: 3 | L6: 2 | M6: 3 | N6: 3 | O6: succulent | P6: annual | Q6: nt | R6: 36069 | T6: 1 | U6: 1
A7: 6 | B7: =E7&" "&F7 -> Drosanthemum intermedium | C7: Aizoaceae | E7: Drosanthemum | F7: intermedium | G7: Dros int | H7: SHRD ERI | I7: 2 | J7: 6 | K7: 3 | L7: 2 | M7: 3 | N7: 5 | O7: Shrublet | P7: perennial | R7: 35947 | T7: 1 | U7: 1
A8: 7 | B8: =E8&" "&F8 -> Galenia ecklonis | C8: Aizoaceae | D8: rooiloodjie | E8: Galenia | F8: ecklonis | G8: Gale eck | H8: SHRD ERI | I8: 2 | J8: 6 | K8: 3 | L8: 3 | M8: 4 | N8: 5 | O8: Shrublet | P8: perennial | R8: 37257 | T8: 1
A9: 8 | B9: =E9&" "&F9 -> Jordaaniella dubia | C9: Aizoaceae | D9: strandvygie | E9: Jordaaniella | F9: dubia | G9: Jord dub | H9: XXXX XXX | I9: 9 | J9: 6 | K9: 9 | L9: 9 | M9: 4 | N9: 9 | O9: Succulent | P9: perennial | R9: 38108 | U9: 1
A10: 9 | B10: =E10&" "&F10 -> Lampranthus aestivus | C10: Aizoaceae | E10: Lampranthus | F10: aestivus | G10: Lamp aes | H10: SHRD SLF | I10: 2 | J10: 6 | K10: 3 | L10: 2 | M10: 3 | N10: 4 | O10: Shrublet* | P10: perennial | T10: 1 | X10: 1
A11: 10 | B11: =E11&" "&F11 -> Lampranthus caudatus | C11: Aizoaceae | E11: Lampranthus | F11: caudatus | G11: Lamp cau | H11: SHRD ERI | I11: 2 | J11: 6 | K11: 3 | L11: 2 | M11: 3 | N11: 5 | O11: Shrublet* | P11: perennial | R11: 36892 | T11: 1 | X11: 1
A12: 11 | B12: =E12&" "&F12 -> Lampranthus explanatus | C12: Aizoaceae | E12: Lampranthus | F12: explanatus | G12: Lamp exp | H12: PERL SLF | I12: 3 | J12: 6 | K12: 5 | L12: 2 | M12: 3 | N12: 4 | O12: Shrublet* | P12: perennial | R12: 35612 | T12: 1 | U12: 1 | V12: 1
A13: 12 | B13: =E13&" "&F13 -> Lampranthus furvus | C13: Aizoaceae | E13: Lampranthus | F13: furvus | G13: Lamp fur | H13: SHRD ERI | I13: 2 | J13: 6 | K13: 2 | L13: 2 | M13: 3 | N13: 5 | O13: Shrublet* | P13: perennial | R13: 35947 | T13: 1 | V13: 1
A14: 13 | B14: =E14&" "&F14 -> Lampranthus simulans | C14: Aizoaceae | E14: Lampranthus | F14: simulans | G14: Lamp sim | H14: SHRD ERI | I14: 2 | J14: 6 | K14: 2 | L14: 2 | M14: 3 | N14: 5 | O14: Shrublet* | P14: perennial | R14: 35886 | T14: 1 | X14: 1
A15: 14 | B15: =E15&" "&F15 -> Phyllobolus canaliculatus | C15: Aizoaceae | E15: Phyllobolus | F15: canaliculatus | G15: Phyl can | H15: GEOL SLF | I15: 4 | J15: 6 | K15: 2 | L15: 2 | M15: 4 | N15: 4 | O15: Geophyte | P15: perennial | R15: 36861 | T15: 1 | W15: 1 | X15: 1
A16: 15 | B16: =E16&" "&F16 -> Ruschia calcicola | C16: Aizoaceae | E16: Ruschia | F16: calcicola | G16: Rusc cal | H16: SHRD SLF | I16: 2 | J16: 6 | K16: 2 | L16: 2 | M16: 3 | N16: 4 | O16: shrublet | P16: perennial | R16: 35947 | T16: 1 | V16: 1
A17: 16 | B17: =E17&" "&F17 -> Ruschia sarmentosa | C17: Aizoaceae | E17: Ruschia | F17: sarmentosa | G17: Rusc sar | H17: SHRD BLF | I17: 2 | J17: 6 | K17: 5 | L17: 2 | M17: 3 | N17: 3 | O17: shrublet | P17: perennial | R17: 35612 | T17: 1 | U17: 1 | V17: 1 | X17: 1
A18: 17 | B18: =E18&" "&F18 -> Tetragonia echinata | C18: Aizoaceae | E18: Tetragonia | F18: echinata | G18: Tetr ech | H18: ANNL SLF | I18: 6 | J18: 6 | K18: 3 | L18: 1 | M18: 3 | N18: 4 | O18: Succulent | P18: annual | R18: 37226 | T18: 1 | U18: 1
A19: 18 | B19: =E19&" "&F19 -> Tetragonia fruticosa | C19: Aizoaceae | D19: kinkelbossie | E19: Tetragonia | F19: fruticosa | G19: Tetr fru | H19: SHRL SLF | I19: 2 | J19: 5 | K19: 3 | L19: 2 | M19: 3 | N19: 4 | O19: shrub | P19: perennial | R19: 35855 | T19: 1 | U19: 1 | Y19: 1
A20: 19 | B20: =E20&" "&F20 -> Tulbaghia capensis | C20: Alliaceae | D20: wild garlic | E20: Tulbaghia | F20: capensis | G20: Tulb cap | H20: GEOL GRA | I20: 4 | J20: 6 | K20: 5 | L20: 3 | M20: 1 | N20: 1 | O20: Geophyte | P20: perennial | R20: 36586 | S20: X | X20: 1
A21: 20 | B21: =E21&" "&F21 -> Exomis microphylla var. axyroides | C21: Amaranthaceae | D21: brakbossie | E21: Exomis | F21: microphylla var. axyroides | G21: Exom mic | H21: SHRL BLS | I21: 2 | J21: 5 | K21: 3 | L21: 2 | M21: 1 | N21: 3 | O21: shrub | P21: perennial | R21: 37012 | T21: 1 | U21: 1
A22: 21 | B22: =E22&" "&F22 -> Brunsvigia orientalis | C22: Amaryllidaceae | D22: candelabra flower | E22: Brunsvigia | F22: orientalis | G22: Brun ori | H22: GEOL BLS | I22: 4 | J22: 6 | K22: 5 | L22: 1 | M22: 1 | N22: 3 | O22: Geophyte | P22: perennial | R22: 35612 | S22: P | U22: 1
A23: 22 | B23: =E23&" "&F23 -> Cyrtanthus leucanthus | C23: Amaryllidaceae | D23: witbrandlelie | E23: Cyrtanthus | F23: leucanthus | G23: Cyrt leu | H23: GEOL BLS | I23: 4 | J23: 6 | K23: 5 | L23: 2 | M23: 1 | N23: 1 | O23: Geophyte | P23: perennial | Q23: R | R23: 35796 | T23: 1 | X23: 1
A24: 23 | B24: =E24&" "&F24 -> Haemanthus coccineus | C24: Amaryllidaceae | D24: April fool, velskoenblaar, brandlelie | E24: Haemanthus | F24: coccineus | G24: Haem coc | H24: GEOL BLF | I24: 4 | J24: 6 | K24: 5 | L24: 1 | M24: 4 | N24: 1 | O24: Geophyte | P24: perennial | R24: 35612 | T24: 1 | U24: 1 | Z24: 1
A25: 24 | B25: =E25&" "&F25 -> Haemanthus sanguineus | C25: Amaryllidaceae | D25: April fool, velskoenblaar, brandlelie | E25: Haemanthus | F25: sanguineus | G25: Haem san | H25: GEOL BLF | I25: 4 | J25: 6 | K25: 5 | L25: 1 | M25: 4 | N25: 1 | O25: Geophyte | P25: perennial | R25: 35855 | T25: 1 | U25: 1
A26: 25 | B26: =E26&" "&F26 -> Nerine humilis | C26: Amaryllidaceae | E26: Nerine | F26: humilis | G26: Neri hum | H26: GEOL XXX | I26: 4 | J26: 6 | K26: 5 | L26: 9 | M26: 9 | N26: 9 | O26: Geophyte | P26: perennial | R26: 38108 | T26: 1 | U26: 1
A27: 26 | B27: =E27&" "&F27 -> Rhus crenata | C27: Anacardiaceae | D27: dune crow-berry, duinekraaibessie | E27: Rhus | F27: crenata | G27: Rhus cre | H27: SHRH SLH | I27: 2 | J27: 3 | K27: 2 | L27: 1 | M27: 2 | N27: 4 | O27: Shrub to tree | P27: perennial | R27: 35796 | T27: 1 | U27: 1
A28: 27 | B28: =E28&" "&F28 -> Rhus glauca | C28: Anacardiaceae | D28: blue kuni-bush, bloukoenibos | E28: Rhus | F28: glauca | G28: Rhus gla | H28: SHRH SLH | I28: 2 | J28: 3 | K28: 2 | L28: 1 | M28: 2 | N28: 4 | O28: Shrub to tree | P28: perennial | R28: 35612 | T28: 1 | U28: 1 | Y28: 1
A29: 28 | B29: =E29&" "&F29 -> Rhus laevigata var. laevigata | C29: Anacardiaceae | D29: dune taaibos, duinetaaibos | E29: Rhus | F29: laevigata var. laevigata | G29: Rhus lae | H29: SHRH BLH | I29: 2 | J29: 3 | K29: 2 | L29: 1 | M29: 2 | N29: 3 | O29: Shrub | P29: perennial | R29: 35612 | T29: 1 | U29: 1 | V29: 1 | Y29: 1
A30: 29 | B30: =E30&" "&F30 -> Rhus laevigata var. villosa | C30: Anacardiaceae | D30: dune taaibos, duinetaaibos | E30: Rhus | F30: laevigata var. villosa | G30: Rhus lae | H30: SHRH BLH | I30: 2 | J30: 3 | K30: 2 | L30: 1 | M30: 2 | N30: 3 | O30: Shrub | P30: perennial | R30: 35612 | U30: 1 | V30: 1
A31: 30 | B31: =E31&" "&F31 -> Rhus lucida | C31: Anacardiaceae | D31: blinktaaibos | E31: Rhus | F31: lucida | G31: Rhus luc | H31: SHRH BLH | I31: 2 | J31: 3 | K31: 2 | L31: 1 | M31: 2 | N31: 3 | O31: Shrub | P31: perennial | R31: 35612 | T31: 1 | U31: 1 | V31: 1 | W31: 1 | X31: 1 | Y31: 1 | AA31: 1
A32: 31 | B32: =E32&" "&F32 -> Rhus rosmarinifolia | C32: Anacardiaceae | D32: roosmaryntaaibos | E32: Rhus | F32: rosmarinifolia | G32: Rhus ros | H32: SHRL NED | I32: 2 | J32: 5 | K32: 2 | L32: 3 | M32: 2 | N32: 3 | O32: Shrub | P32: perennial | R32: 35612 | T32: 1 | V32: 1 | X32: 1
A33: 32 | B33: =E33&" "&F33 -> Rhus tomentosa | C33: Anacardiaceae | D33: wild currant, korentebos | E33: Rhus | F33: tomentosa | G33: Rhus tom | H33: SHRH BLH | I33: 2 | J33: 3 | K33: 2 | L33: 1 | M33: 2 | N33: 3 | O33: Shrub to tree | P33: perennial | R33: 35886 | T33: 1 | U33: 1 | Z33: 1
A34: 33 | B34: =E34&" "&F34 -> Annesorhiza macrocarpa | C34: Apiaceae | D34: wilde-anyswortel | E34: Annesorhiza | F34: macrocarpa | G34: Anne mac | H34: PERH PIN | I34: 3 | J34: 4 | K34: 2 | L34: 5 | M34: 1 | N34: 2 | P34: perennial | R34: 35612 | T34: 1 | V34: 1
A35: 34 | B35: =E35&" "&F35 -> Arctopus echinatus | C35: Apiaceae | D35: platdoring, pokkiesdoring | E35: Arctopus | F35: echinatus | G35: Arct ech | H35: PERL BLH | I35: 3 | J35: 6 | K35: 5 | L35: 1 | M35: 2 | N35: 1 | O35: herb | P35: perennial | R35: 35855 | T35: 1 | X35: 1
A36: 35 | B36: =E36&" "&F36 -> Berula erecta ssp. thunbergii | C36: Apiaceae | D36: tandpynwortel, water parsnip | E36: Berula | F36: erecta ssp. thunbergii | G36: Beru ere | H36: ANNM SLS | I36: 6 | J36: 5 | K36: 4 | L36: 1 | M36: 1 | N36: 4 | O36: herb | P36: annual | R36: 35947 | T36: 1 | AA36: 1
A37: 36 | B37: =E37&" "&F37 -> Hermas villosa | C37: Apiaceae | D37: tontelblaar, tonteldoek | E37: Hermas | F37: villosa | G37: Herm vil | H37: SHRL BLH | I37: 2 | J37: 5 | K37: 5 | L37: 1 | M37: 2 | N37: 2 | O37: Shrub | P37: perennial | R37: 35612 | T37: 1 | X37: 1
A38: 37 | B38: =E38&" "&F38 -> Itasina filifolia | C38: Apiaceae | D38: grass-parsley | E38: Itasina | F38: filifolia | G38: Itas fil | H38: PERL APH | I38: 3 | J38: 6 | K38: 0 | L38: 7 | M38: 0 | N38: 0 | O38: herb | P38: perennial | R38: 36923 | T38: 1 | X38: 1
A39: 38 | B39: =E39&" "&F39 -> Peucedanum capillaceum | C39: Apiaceae | E39: Peucedanum | F39: capillaceum | G39: Peuc cap | H39: PERM PIN | I39: 3 | J39: 5 | K39: 2 | L39: 5 | M39: 1 | N39: 3 | O39: herb | P39: perennial | R39: 36923 | T39: 1 | X39: 1
A40: 39 | B40: =E40&" "&F40 -> Peucedanum ferulaceum | C40: Apiaceae | D40: bergseldery | E40: Peucedanum | F40: ferulaceum | G40: Peuc fer | H40: PERH PIN | I40: 3 | J40: 4 | K40: 4 | L40: 5 | M40: 1 | N40: 3 | O40: shrub | P40: perennial | R40: 36161 | T40: 1 | U40: 1 | X40: 1
...

Sheet flora
A1: 09.11. 2004 | B1: taxon | D1: taxon | G1: abbreviations | I1: life form (Mergili) | O1: life form (Gernandt & Privett) | Q1: status (red data) | R1: record | U1: Habitat
B2: scientific name | C2: family | D2: Common Name | E2: genus | F2: species | G2: taxon | H2: life form | I2: 1 | J2: 2 | K2: 3 | L2: 4 | M2: 5 | N2: 6 | R2: date | S2: to collect | T2: collected | U2: DN | V2: LS | W2: SP | X2: TM | Y2: MW | Z2: AM | AA2: WL | AB2: RP
A3: 1 | B3: =E3&" "&F3 -> Agapanthus africanus | C3: Agapanthaceae | D3: bloulelie | E3: Agapanthus | F3: africanus | G3: Agap afr | H3: GEOL BLS | I3: 4 | J3: 6 | K3: 5 | L3: 2 | M3: 1 | N3: 1 | O3: Geophyte | P3: perennial | R3: 35612 | S3: X | U3: 1
A4: 2 | B4: =E4&" "&F4 -> Carpanthea pomeridiana | C4: Aizoaceae | D4: vetkousie | E4: Carpanthea | F4: pomeridiana | G4: Carp pom | H4: ANNL BLF | I4: 6 | J4: 6 | K4: 3 | L4: 1 | M4: 4 | N4: 3 | O4: herb | P4: annual | R4: 36069 | T4: 1 | U4: 1
A5: 3 | B5: =E5&" "&F5 -> Carpobrotus acinaciformis | C5: Aizoaceae | D5: hottentot fig, sour fig, suurvy | E5: Carpobrotus | F5: acinaciformis | G5: Carp aci | H5: PERL BLF | I5: 3 | J5: 6 | K5: 3 | L5: 2 | M5: 3 | N5: 3 | O5: Succulent | P5: perennial | R5: 35612 | T5: 1 | U5: 1 | V5: 1 | W5: 1 | X5: 1 | AB5: 1
A6: 4 | B6: =E6&" "&F6 -> Carpobrotus edulis | C6: Aizoaceae | D6: hottentot fig, sour fig, suurvy | E6: Carpobrotus | F6: edulis | G6: Carp edu | H6: PERL BLF | I6: 3 | J6: 6 | K6: 3 | L6: 2 | M6: 3 | N6: 3 | O6: Succulent | P6: perennial | R6: 35612 | T6: 1 | U6: 1
A7: 5 | B7: =E7&" "&F7 -> Dorotheanthus bellidiformis | C7: Aizoaceae | D7: livingstone daisy, bokbaaivygie | E7: Dorotheanthus | F7: bellidiformis | G7: Doro bel | H7: ANNL BLF | I7: 6 | J7: 6 | K7: 3 | L7: 2 | M7: 3 | N7: 3 | O7: succulent | P7: annual | Q7: nt | R7: 36069 | T7: 1 | U7: 1
A8: 6 | B8: =E8&" "&F8 -> Drosanthemum intermedium | C8: Aizoaceae | E8: Drosanthemum | F8: intermedium | G8: Dros int | H8: SHRD ERI | I8: 2 | J8: 6 | K8: 3 | L8: 2 | M8: 3 | N8: 5 | O8: Shrublet | P8: perennial | R8: 35947 | T8: 1 | U8: 1
A9: 7 | B9: =E9&" "&F9 -> Galenia ecklonis | C9: Aizoaceae | D9: rooiloodjie | E9: Galenia | F9: ecklonis | G9: Gale eck | H9: SHRD ERI | I9: 2 | J9: 6 | K9: 3 | L9: 3 | M9: 4 | N9: 5 | O9: Shrublet | P9: perennial | R9: 37257 | T9: 1
A10: 8 | B10: =E10&" "&F10 -> Jordaaniella dubia | C10: Aizoaceae | D10: strandvygie | E10: Jordaaniella | F10: dubia | G10: Jord dub | H10: XXXX XXX | I10: 9 | J10: 6 | K10: 9 | L10: 9 | M10: 4 | N10: 9 | O10: Succulent | P10: perennial | R10: 38108 | U10: 1
A11: 9 | B11: =E11&" "&F11 -> Lampranthus aestivus | C11: Aizoaceae | E11: Lampranthus | F11: aestivus | G11: Lamp aes | H11: SHRD SLF | I11: 2 | J11: 6 | K11: 3 | L11: 2 | M11: 3 | N11: 4 | O11: Shrublet* | P11: perennial | T11: 1 | X11: 1
A12: 10 | B12: =E12&" "&F12 -> Lampranthus caudatus | C12: Aizoaceae | E12: Lampranthus | F12: caudatus | G12: Lamp cau | H12: SHRD ERI | I12: 2 | J12: 6 | K12: 3 | L12: 2 | M12: 3 | N12: 5 | O12: Shrublet* | P12: perennial | R12: 36892 | T12: 1 | X12: 1
A13: 11 | B13: =E13&" "&F13 -> Lampranthus explanatus | C13: Aizoaceae | E13: Lampranthus | F13: explanatus | G13: Lamp exp | H13: PERL SLF | I13: 3 | J13: 6 | K13: 5 | L13: 2 | M13: 3 | N13: 4 | O13: Shrublet* | P13: perennial | R13: 35612 | T13: 1 | U13: 1 | V13: 1
A14: 12 | B14: =E14&" "&F14 -> Lampranthus furvus | C14: Aizoaceae | E14: Lampranthus | F14: furvus | G14: Lamp fur | H14: SHRD ERI | I14: 2 | J14: 6 | K14: 2 | L14: 2 | M14: 3 | N14: 5 | O14: Shrublet* | P14: perennial | R14: 35947 | T14: 1 | V14: 1
A15: 13 | B15: =E15&" "&F15 -> Lampranthus simulans | C15: Aizoaceae | E15: Lampranthus | F15: simulans | G15: Lamp sim | H15: SHRD ERI | I15: 2 | J15: 6 | K15: 2 | L15: 2 | M15: 3 | N15: 5 | O15: Shrublet* | P15: perennial | R15: 35886 | T15: 1 | X15: 1
A16: 14 | B16: =E16&" "&F16 -> Phyllobolus canaliculatus | C16: Aizoaceae | E16: Phyllobolus | F16: canaliculatus | G16: Phyl can | H16: GEOL SLF | I16: 4 | J16: 6 | K16: 2 | L16: 2 | M16: 4 | N16: 4 | O16: Geophyte | P16: perennial | R16: 36861 | T16: 1 | W16: 1 | X16: 1
A17: 15 | B17: =E17&" "&F17 -> Ruschia calcicola | C17: Aizoaceae | E17: Ruschia | F17: calcicola | G17: Rusc cal | H17: SHRD SLF | I17: 2 | J17: 6 | K17: 2 | L17: 2 | M17: 3 | N17: 4 | O17: shrublet | P17: perennial | R17: 35947 | T17: 1 | V17: 1
A18: 16 | B18: =E18&" "&F18 -> Ruschia sarmentosa | C18: Aizoaceae | E18: Ruschia | F18: sarmentosa | G18: Rusc sar | H18: SHRD BLF | I18: 2 | J18: 6 | K18: 5 | L18: 2 | M18: 3 | N18: 3 | O18: shrublet | P18: perennial | R18: 35612 | T18: 1 | U18: 1 | V18: 1 | X18: 1
A19: 17 | B19: =E19&" "&F19 -> Tetragonia echinata | C19: Aizoaceae | E19: Tetragonia | F19: echinata | G19: Tetr ech | H19: ANNL SLF | I19: 6 | J19: 6 | K19: 3 | L19: 1 | M19: 3 | N19: 4 | O19: Succulent | P19: annual | R19: 37226 | T19: 1 | U19: 1
A20: 18 | B20: =E20&" "&F20 -> Tetragonia fruticosa | C20: Aizoaceae | D20: kinkelbossie | E20: Tetragonia | F20: fruticosa | G20: Tetr fru | H20: SHRL SLF | I20: 2 | J20: 5 | K20: 3 | L20: 2 | M20: 3 | N20: 4 | O20: shrub | P20: perennial | R20: 35855 | T20: 1 | U20: 1 | Y20: 1
A21: 19 | B21: =E21&" "&F21 -> Tulbaghia capensis | C21: Alliaceae | D21: wild garlic | E21: Tulbaghia | F21: capensis | G21: Tulb cap | H21: GEOL GRA | I21: 4 | J21: 6 | K21: 5 | L21: 3 | M21: 1 | N21: 1 | O21: Geophyte | P21: perennial | R21: 36586 | S21: X | X21: 1
A22: 20 | B22: =E22&" "&F22 -> Exomis microphylla var. axyroides | C22: Amaranthaceae | D22: brakbossie | E22: Exomis | F22: microphylla var. axyroides | G22: Exom mic | H22: SHRL BLS | I22: 2 | J22: 5 | K22: 3 | L22: 2 | M22: 1 | N22: 3 | O22: shrub | P22: perennial | R22: 37012 | T22: 1 | U22: 1
A23: 21 | B23: =E23&" "&F23 -> Brunsvigia orientalis | C23: Amaryllidaceae | D23: candelabra flower | E23: Brunsvigia | F23: orientalis | G23: Brun ori | H23: GEOL BLS | I23: 4 | J23: 6 | K23: 5 | L23: 1 | M23: 1 | N23: 3 | O23: Geophyte | P23: perennial | R23: 35612 | S23: P | U23: 1
A24: 22 | B24: =E24&" "&F24 -> Cyrtanthus leucanthus | C24: Amaryllidaceae | D24: witbrandlelie | E24: Cyrtanthus | F24: leucanthus | G24: Cyrt leu | H24: GEOL BLS | I24: 4 | J24: 6 | K24: 5 | L24: 2 | M24: 1 | N24: 1 | O24: Geophyte | P24: perennial | Q24: R | R24: 35796 | T24: 1 | X24: 1
A25: 23 | B25: =E25&" "&F25 -> Haemanthus coccineus | C25: Amaryllidaceae | D25: April fool, velskoenblaar, brandlelie | E25: Haemanthus | F25: coccineus | G25: Haem coc | H25: GEOL BLF | I25: 4 | J25: 6 | K25: 5 | L25: 1 | M25: 4 | N25: 1 | O25: Geophyte | P25: perennial | R25: 35612 | T25: 1 | U25: 1 | Z25: 1
A26: 24 | B26: =E26&" "&F26 -> Haemanthus sanguineus | C26: Amaryllidaceae | D26: April fool, velskoenblaar, brandlelie | E26: Haemanthus | F26: sanguineus | G26: Haem san | H26: GEOL BLF | I26: 4 | J26: 6 | K26: 5 | L26: 1 | M26: 4 | N26: 1 | O26: Geophyte | P26: perennial | R26: 35855 | T26: 1 | U26: 1
A27: 25 | B27: =E27&" "&F27 -> Nerine humilis | C27: Amaryllidaceae | E27: Nerine | F27: humilis | G27: Neri hum | H27: GEOL XXX | I27: 4 | J27: 6 | K27: 5 | L27: 9 | M27: 9 | N27: 9 | O27: Geophyte | P27: perennial | R27: 38108 | T27: 1 | U27: 1
A28: 26 | B28: =E28&" "&F28 -> Rhus crenata | C28: Anacardiaceae | D28: dune crow-berry, duinekraaibessie | E28: Rhus | F28: crenata | G28: Rhus cre | H28: SHRH SLH | I28: 2 | J28: 3 | K28: 2 | L28: 1 | M28: 2 | N28: 4 | O28: Shrub to tree | P28: perennial | R28: 35796 | T28: 1 | U28: 1
A29: 27 | B29: =E29&" "&F29 -> Rhus glauca | C29: Anacardiaceae | D29: blue kuni-bush, bloukoenibos | E29: Rhus | F29: glauca | G29: Rhus gla | H29: SHRH SLH | I29: 2 | J29: 3 | K29: 2 | L29: 1 | M29: 2 | N29: 4 | O29: Shrub to tree | P29: perennial | R29: 35612 | T29: 1 | U29: 1 | Y29: 1
A30: 28 | B30: =E30&" "&F30 -> Rhus laevigata var. laevigata | C30: Anacardiaceae | D30: dune taaibos, duinetaaibos | E30: Rhus | F30: laevigata var. laevigata | G30: Rhus lae | H30: SHRH BLH | I30: 2 | J30: 3 | K30: 2 | L30: 1 | M30: 2 | N30: 3 | O30: Shrub | P30: perennial | R30: 35612 | T30: 1 | U30: 1 | V30: 1 | Y30: 1
A31: 29 | B31: =E31&" "&F31 -> Rhus laevigata var. villosa | C31: Anacardiaceae | D31: dune taaibos, duinetaaibos | E31: Rhus | F31: laevigata var. villosa | G31: Rhus lae | H31: SHRH BLH | I31: 2 | J31: 3 | K31: 2 | L31: 1 | M31: 2 | N31: 3 | O31: Shrub | P31: perennial | R31: 35612 | U31: 1 | V31: 1
A32: 30 | B32: =E32&" "&F32 -> Rhus lucida | C32: Anacardiaceae | D32: blinktaaibos | E32: Rhus | F32: lucida | G32: Rhus luc | H32: SHRH BLH | I32: 2 | J32: 3 | K32: 2 | L32: 1 | M32: 2 | N32: 3 | O32: Shrub | P32: perennial | R32: 35612 | T32: 1 | U32: 1 | V32: 1 | W32: 1 | X32: 1 | Y32: 1 | AA32: 1
A33: 31 | B33: =E33&" "&F33 -> Rhus rosmarinifolia | C33: Anacardiaceae | D33: roosmaryntaaibos | E33: Rhus | F33: rosmarinifolia | G33: Rhus ros | H33: SHRL NED | I33: 2 | J33: 5 | K33: 2 | L33: 3 | M33: 2 | N33: 3 | O33: Shrub | P33: perennial | R33: 35612 | T33: 1 | V33: 1 | X33: 1
A34: 32 | B34: =E34&" "&F34 -> Rhus tomentosa | C34: Anacardiaceae | D34: wild currant, korentebos | E34: Rhus | F34: tomentosa | G34: Rhus tom | H34: SHRH BLH | I34: 2 | J34: 3 | K34: 2 | L34: 1 | M34: 2 | N34: 3 | O34: Shrub to tree | P34: perennial | R34: 35886 | T34: 1 | U34: 1 | Z34: 1
A35: 33 | B35: =E35&" "&F35 -> Annesorhiza macrocarpa | C35: Apiaceae | D35: wilde-anyswortel | E35: Annesorhiza | F35: macrocarpa | G35: Anne mac | H35: PERH PIN | I35: 3 | J35: 4 | K35: 2 | L35: 5 | M35: 1 | N35: 2 | P35: perennial | R35: 35612 | T35: 1 | V35: 1
A36: 34 | B36: =E36&" "&F36 -> Arctopus echinatus | C36: Apiaceae | D36: platdoring, pokkiesdoring | E36: Arctopus | F36: echinatus | G36: Arct ech | H36: PERL BLH | I36: 3 | J36: 6 | K36: 5 | L36: 1 | M36: 2 | N36: 1 | O36: herb | P36: perennial | R36: 35855 | T36: 1 | X36: 1
A37: 35 | B37: =E37&" "&F37 -> Berula erecta ssp. thunbergii | C37: Apiaceae | D37: tandpynwortel, water parsnip | E37: Berula | F37: erecta ssp. thunbergii | G37: Beru ere | H37: ANNM SLS | I37: 6 | J37: 5 | K37: 4 | L37: 1 | M37: 1 | N37: 4 | O37: herb | P37: annual | R37: 35947 | T37: 1 | AA37: 1
A38: 36 | B38: =E38&" "&F38 -> Hermas villosa | C38: Apiaceae | D38: tontelblaar, tonteldoek | E38: Hermas | F38: villosa | G38: Herm vil | H38: SHRL BLH | I38: 2 | J38: 5 | K38: 5 | L38: 1 | M38: 2 | N38: 2 | O38: Shrub | P38: perennial | R38: 35612 | T38: 1 | X38: 1
A39: 37 | B39: =E39&" "&F39 -> Itasina filifolia | C39: Apiaceae | D39: grass-parsley | E39: Itasina | F39: filifolia | G39: Itas fil | H39: PERL APH | I39: 3 | J39: 6 | K39: 0 | L39: 7 | M39: 0 | N39: 0 | O39: herb | P39: perennial | R39: 36923 | T39: 1 | X39: 1
A40: 38 | B40: =E40&" "&F40 -> Peucedanum capillaceum | C40: Apiaceae | E40: Peucedanum | F40: capillaceum | G40: Peuc cap | H40: PERM PIN | I40: 3 | J40: 5 | K40: 2 | L40: 5 | M40: 1 | N40: 3 | O40: herb | P40: perennial | R40: 36923 | T40: 1 | X40: 1
...

Sheet releves
A1: rel. | B1: type | C1: formation | D1: statistics | F1: releve | K1: sampling | M1: coordinates [m UTM WGS84] | O1: altitude [m] | R1: slope [°] | U1: aspect [°] | Y1: advanced topography (DEM) | AB1: vegetation age | AE1: soil physical properties | AI1: soil chemical properties | AP1: Nr. old
D2: a-diversity [sp.] | E2: total cover [%] | F2: dir. | G2: SW | H2: SE | I2: NW | J2: NE | K2: date | L2: researcher | M2: x | N2: y | O2: GPS | P2: altimeter | Q2: DEM | R2: clinometer | S2: DEM | T2: value | U2: compass | V2: DEM | W2: value | X2: code | Y2: flow | Z2: irradiation | AA2: wind | AB2: fire [record] | AC2: fire [map] | AD2: age [a] | AE2: substrate | AF2: soil depth [cm] | AG2: rock cover [%] | AH2: texture | AI2: pH | AJ2: res. | AK2: Na | AL2: P | AM2: K | AN2: Ca | AO2: Mg
A3: 1 | B3: core | C3: Milkwood Scrub Forest | D3: 12 | E3: 128.5 | F3: N | G3: IP | H3: NN | I3: NN | J3: NN | K3: 35600 | L3: G. Siebritz | M3: 354569 | N3: 6176568 | O3: ND | P3: ND | Q3: 225 | R3: 35 | S3: 16 | T3: =IF(OR(R3="ND",R3=""),S3,R3) -> 35 | V3: 209 | W3: =IF(OR(U3="ND",U3=""),V3,U3) -> 209 | X3: 1 | Y3: 0.54 | Z3: 89172 | AA3: 1361 | AB3: 999 | AC3: 0 | AD3: =IF(AC3=0,1000,IF(AC3=9999,"ND",(K3/365.25+1899)-AC3)) -> 1000 | AE3: 5 | AF3: 100 | AG3: 0 | AH3: Sand | AI3: 7.4 | AJ3: 590 | AK3: 216 | AL3: 156 | AM3: 147 | AN3: 42.05 | AO3: 6.92 | AP3: 1
A4: 2 | B4: core | C4: Milkwood Scrub Forest | D4: 12 | E4: 216.5 | F4: N | G4: IP | H4: NN | I4: NN | J4: NN | K4: 35600 | L4: G. Siebritz | M4: 354652 | N4: 6176530 | O4: ND | P4: ND | Q4: 225 | R4: 0 | S4: 10 | T4: =IF(OR(R4="ND",R4=""),S4,R4) -> 0 | V4: 217 | W4: =IF(OR(U4="ND",U4=""),V4,U4) -> 217 | X4: 0 | Y4: 1.296 | Z4: 96788 | AA4: 1241 | AB4: 999 | AC4: 0 | AD4: =IF(AC4=0,1000,IF(AC4=9999,"ND",(K4/365.25+1899)-AC4)) -> 1000 | AE4: 4 | AF4: 100 | AG4: 0 | AH4: Sand | AI4: 7.5 | AJ4: 640 | AK4: 173 | AL4: 129 | AM4: 125 | AN4: 36.04 | AO4: 4.49 | AP4: 2
A5: 3 | B5: core | C5: Milkwood Scrub Forest | D5: 13 | E5: 109 | F5: N | G5: IP | H5: NN | I5: NN | J5: NN | K5: 35601 | L5: G. Siebritz | M5: 354967 | N5: 6176375 | O5: ND | P5: ND | Q5: 233 | R5: 5 | S5: 8 | T5: =IF(OR(R5="ND",R5=""),S5,R5) -> 5 | V5: 198 | W5: =IF(OR(U5="ND",U5=""),V5,U5) -> 198 | X5: 2 | Y5: 0.159 | Z5: 98648 | AA5: 1438 | AB5: 999 | AC5: 0 | AD5: =IF(AC5=0,1000,IF(AC5=9999,"ND",(K5/365.25+1899)-AC5)) -> 1000 | AE5: 4 | AF5: 100 | AG5: 0 | AH5: Sand | AI5: 7.5 | AJ5: 490 | AK5: 238 | AL5: 121 | AM5: 179 | AN5: 54.5 | AO5: 5.98 | AP5: 3
A6: 4 | B6: core | C6: Afromontane Forest | D6: 18 | E6: 137 | F6: N | G6: IP | H6: NN | I6: NN | J6: NN | K6: 35601 | L6: G. Siebritz | M6: 356748 | N6: 6176730 | O6: ND | P6: ND | Q6: 332 | R6: 40 | S6: 7 | T6: =IF(OR(R6="ND",R6=""),S6,R6) -> 40 | V6: 155 | W6: =IF(OR(U6="ND",U6=""),V6,U6) -> 155 | X6: 3 | Y6: 1.755 | Z6: 98799 | AA6: 832 | AB6: 999 | AC6: 0 | AD6: =IF(AC6=0,1000,IF(AC6=9999,"ND",(K6/365.25+1899)-AC6)) -> 1000 | AE6: 1 | AF6: 35 | AG6: 10 | AH6: Sand | AI6: 6.4 | AJ6: 440 | AK6: 169 | AL6: 126 | AM6: 207 | AN6: 43.02 | AO6: 7.24 | AP6: 4
A7: 5 | B7: core | C7: Afromontane Forest | D7: 16 | E7: 128.5 | F7: N | G7: IP | H7: NN | I7: NN | J7: NN | K7: 35611 | L7: G. Siebritz | M7: 356754 | N7: 6176646 | O7: ND | P7: ND | Q7: 324 | R7: 40 | S7: 15 | T7: =IF(OR(R7="ND",R7=""),S7,R7) -> 40 | V7: 179 | W7: =IF(OR(U7="ND",U7=""),V7,U7) -> 179 | X7: 3 | Y7: 0.913 | Z7: 88113 | AA7: 927 | AB7: 999 | AC7: 0 | AD7: =IF(AC7=0,1000,IF(AC7=9999,"ND",(K7/365.25+1899)-AC7)) -> 1000 | AE7: 1 | AF7: 45 | AG7: 3 | AH7: Sand | AI7: 6.1 | AJ7: 530 | AK7: 265 | AL7: 63 | AM7: 175 | AN7: 33.53 | AO7: 8.3 | AP7: 5
A8: 6 | B8: core | C8: Afromontane Forest | D8: 12 | E8: 121 | F8: N | G8: IP | H8: NN | I8: NN | J8: NN | K8: 35612 | L8: G. Siebritz | M8: 356754 | N8: 6176549 | O8: ND | P8: ND | Q8: 295 | R8: 20 | S8: 35 | T8: =IF(OR(R8="ND",R8=""),S8,R8) -> 20 | V8: 227 | W8: =IF(OR(U8="ND",U8=""),V8,U8) -> 227 | X8: 0 | Y8: 0.669 | Z8: 67548 | AA8: 480 | AB8: 999 | AC8: 0 | AD8: =IF(AC8=0,1000,IF(AC8=9999,"ND",(K8/365.25+1899)-AC8)) -> 1000 | AE8: 1 | AF8: 35 | AG8: 20 | AH8: Sand | AI8: 7.1 | AJ8: 260 | AK8: 99 | AL8: 128 | AM8: 116 | AN8: 40.07 | AO8: 4.01 | AP8: 6
A9: 7 | B9: core | C9: Afromontane Forest | D9: 8 | E9: 108.5 | F9: N | G9: IP | H9: NN | I9: NN | J9: NN | K9: 35613 | L9: G. Siebritz | M9: 356783 | N9: 6176517 | O9: ND | P9: ND | Q9: 285 | R9: 40 | S9: 40 | T9: =IF(OR(R9="ND",R9=""),S9,R9) -> 40 | V9: 190 | W9: =IF(OR(U9="ND",U9=""),V9,U9) -> 190 | X9: 0 | Y9: 0.076 | Z9: 48215 | AA9: 311 | AB9: 999 | AC9: 0 | AD9: =IF(AC9=0,1000,IF(AC9=9999,"ND",(K9/365.25+1899)-AC9)) -> 1000 | AE9: 1 | AF9: 35 | AG9: 5 | AH9: Sand | AI9: 7.1 | AJ9: 290 | AK9: 206 | AL9: 217 | AM9: 364 | AN9: 52.2 | AO9: 8.13 | AP9: 7
A10: 8 | B10: core | C10: Afromontane Forest | D10: 14 | E10: 126 | F10: N | G10: IP | H10: NN | I10: NN | J10: NN | K10: 35613 | L10: G. Siebritz | M10: 356829 | N10: 6176537 | O10: ND | P10: ND | Q10: 306 | R10: 45 | S10: 41 | T10: =IF(OR(R10="ND",R10=""),S10,R10) -> 45 | V10: 200 | W10: =IF(OR(U10="ND",U10=""),V10,U10) -> 200 | X10: 0 | Y10: 0.635 | Z10: 49015 | AA10: 539 | AB10: 999 | AC10: 0 | AD10: =IF(AC10=0,1000,IF(AC10=9999,"ND",(K10/365.25+1899)-AC10)) -> 1000 | AE10: 1 | AF10: 35 | AG10: 15 | AH10: Sand | AI10: 6 | AJ10: 320 | AK10: 296 | AL10: 139 | AM10: 311 | AN10: 39.8 | AO10: 7.79 | AP10: 8
A11: 9 | B11: core | C11: Dune Asteraceous Fynbos | D11: 34 | E11: 194.5 | F11: N | G11: IP | H11: NN | I11: NN | J11: NN | K11: 35614 | L11: G. Siebritz | M11: 354471 | N11: 6176855 | O11: ND | P11: ND | Q11: 238 | R11: 2 | S11: 5 | T11: =IF(OR(R11="ND",R11=""),S11,R11) -> 2 | V11: 285 | W11: =IF(OR(U11="ND",U11=""),V11,U11) -> 285 | X11: 3 | Y11: 1.213 | Z11: 107814 | AA11: 917 | AB11: ND | AC11: 1988 | AD11: =IF(AC11=0,1000,IF(AC11=9999,"ND",(K11/365.25+1899)-AC11)) -> 8.5058179 | AE11: 3 | AF11: 100 | AG11: 0 | AH11: Sand | AI11: 7.9 | AJ11: 2100 | AK11: 110 | AL11: 35 | AM11: 21 | AN11: 26.45 | AO11: 2.1 | AP11: 9
A12: 10 | B12: core | C12: Dune Asteraceous Fynbos | D12: 31 | E12: 140 | F12: N | G12: IP | H12: NN | I12: NN | J12: NN | K12: 35618 | L12: G. Siebritz | M12: 354193 | N12: 6176715 | O12: ND | P12: 130 | Q12: 201 | R12: 2 | S12: 5 | T12: =IF(OR(R12="ND",R12=""),S12,R12) -> 2 | V12: 226 | W12: =IF(OR(U12="ND",U12=""),V12,U12) -> 226 | X12: 3 | Y12: 1.439 | Z12: 102326 | AA12: 1380 | AB12: ND | AC12: 1988 | AD12: =IF(AC12=0,1000,IF(AC12=9999,"ND",(K12/365.25+1899)-AC12)) -> 8.5167693 | AE12: 6 | AF12: 100 | AG12: 0 | AH12: Sand | AI12: 8 | AJ12: 2460 | AK12: 104 | AL12: 36 | AM12: 11 | AN12: 29.61 | AO12: 2.45 | AP12: 10
A13: 11 | B13: core | C13: Dune Asteraceous Fynbos | D13: 27 | E13: 110 | F13: N | G13: IP | H13: NN | I13: NN | J13: NN | K13: 35619 | L13: G. Siebritz | M13: 354397 | N13: 6177243 | O13: ND | P13: 130 | Q13: 223 | R13: 2 | S13: 5 | T13: =IF(OR(R13="ND",R13=""),S13,R13) -> 2 | V13: 305 | W13: =IF(OR(U13="ND",U13=""),V13,U13) -> 305 | X13: 3 | Y13: 1.152 | Z13: 109535 | AA13: 1202 | AB13: ND | AC13: 1988 | AD13: =IF(AC13=0,1000,IF(AC13=9999,"ND",(K13/365.25+1899)-AC13)) -> 8.5195072 | AE13: 6 | AF13: 100 | AG13: 0 | AH13: Sand | AI13: 8.1 | AJ13: 2500 | AK13: 76 | AL13: 23 | AM13: 15 | AN13: 26.88 | AO13: 1.8 | AP13: 11
A14: 12 | B14: core | C14: Dune Asteraceous Fynbos | D14: 22 | E14: 156 | F14: N | G14: IP | H14: NN | I14: NN | J14: NN | K14: 35621 | L14: G. Siebritz | M14: 354444 | N14: 6177191 | O14: ND | P14: 150 | Q14: 228 | R14: 2 | S14: 4 | T14: =IF(OR(R14="ND",R14=""),S14,R14) -> 2 | V14: 311 | W14: =IF(OR(U14="ND",U14=""),V14,U14) -> 311 | X14: 3 | Y14: 0.818 | Z14: 109381 | AA14: 1214 | AB14: ND | AC14: 1988 | AD14: =IF(AC14=0,1000,IF(AC14=9999,"ND",(K14/365.25+1899)-AC14)) -> 8.5249829 | AE14: 6 | AF14: 100 | AG14: 0 | AH14: Sand | AI14: 8 | AJ14: 2160 | AK14: 81 | AL14: 30 | AM14: 16 | AN14: 25.6 | AO14: 1.78 | AP14: 12
A15: 13 | B15: core | C15: Dune Asteraceous Fynbos | D15: 39 | E15: 111 | F15: N | G15: IP | H15: NN | I15: NN | J15: NN | K15: 35625 | L15: G. Siebritz | M15: 354534 | N15: 6176788 | O15: ND | P15: ND | Q15: 251 | R15: 20 | S15: 16 | T15: =IF(OR(R15="ND",R15=""),S15,R15) -> 20 | V15: 310 | W15: =IF(OR(U15="ND",U15=""),V15,U15) -> 310 | X15: 4 | Y15: 0.705 | Z15: 113193 | AA15: 658 | AB15: ND | AC15: 1988 | AD15: =IF(AC15=0,1000,IF(AC15=9999,"ND",(K15/365.25+1899)-AC15)) -> 8.5359343 | AE15: 2 | AF15: 0 | AG15: 25 | AH15: Sand | AI15: 8 | AJ15: 1570 | AK15: 69 | AL15: 19 | AM15: 23 | AN15: 24.87 | AO15: 1.8 | AP15: 13
A16: 14 | B16: core | C16: Neutral Sand Proteoid Fynbos | D16: 36 | E16: 112 | F16: N | G16: IP | H16: NN | I16: NN | J16: NN | K16: 35632 | L16: G. Siebritz | M16: 354448 | N16: 6176758 | O16: ND | P16: ND | Q16: 240 | R16: 2 | S16: 11 | T16: =IF(OR(R16="ND",R16=""),S16,R16) -> 2 | V16: 271 | W16: =IF(OR(U16="ND",U16=""),V16,U16) -> 271 | X16: 4 | Y16: 0.261 | Z16: 105498 | AA16: 1062 | AB16: 10 | AC16: 1988 | AD16: =IF(AC16=0,1000,IF(AC16=9999,"ND",(K16/365.25+1899)-AC16)) -> 8.5550992 | AE16: 1 | AF16: 0 | AG16: 20 | AH16: Sand | AI16: 7.7 | AJ16: 1240 | AK16: 134 | AL16: 55 | AM16: 55 | AN16: 46.26 | AO16: 2.64 | AP16: 14
A17: 15 | B17: core | C17: Dune Asteraceous Fynbos (disturbed) | D17: 18 | E17: 130 | F17: N | G17: IP | H17: NN | I17: NN | J17: NN | K17: 35632 | L17: G. Siebritz | M17: 355364 | N17: 6176396 | O17: ND | P17: 150 | Q17: 241 | R17: 8 | S17: 4 | T17: =IF(OR(R17="ND",R17=""),S17,R17) -> 8 | V17: 114 | W17: =IF(OR(U17="ND",U17=""),V17,U17) -> 114 | X17: 2 | Y17: 0.005 | Z17: 103375 | AA17: 639 | AB17: ND | AC17: 1990 | AD17: =IF(AC17=0,1000,IF(AC17=9999,"ND",(K17/365.25+1899)-AC17)) -> 6.5550992 | AE17: 3 | AF17: 100 | AG17: 0 | AH17: Sand | AI17: 8 | AJ17: 2340 | AK17: 116 | AL17: 44 | AM17: 16 | AN17: 56 | AO17: 1.51 | AP17: 15
A18: 16 | B18: core | C18: Dune Asteraceous Fynbos | D18: 33 | E18: 112.5 | F18: N | G18: IP | H18: NN | I18: NN | J18: NN | K18: 35633 | L18: G. Siebritz | M18: 355321 | N18: 6176331 | O18: ND | P18: ND | Q18: 246 | R18: 30 | S18: 14 | T18: =IF(OR(R18="ND",R18=""),S18,R18) -> 30 | V18: 318 | W18: =IF(OR(U18="ND",U18=""),V18,U18) -> 318 | X18: 6 | Y18: 0.552 | Z18: 113614 | AA18: 722 | AB18: 2 | AC18: 1990 | AD18: =IF(AC18=0,1000,IF(AC18=9999,"ND",(K18/365.25+1899)-AC18)) -> 6.5578371 | AE18: 2 | AF18: 12 | AG18: 40 | AH18: Sand | AI18: 8 | AJ18: 1320 | AK18: 46 | AL18: 22 | AM18: 26 | AN18: 29.3 | AO18: 2.09 | AP18: 16
A19: 17 | B19: core | C19: Dune Asteraceous Fynbos | D19: 26 | E19: 115.5 | F19: N | G19: IP | H19: NN | I19: NN | J19: NN | K19: 35633 | L19: G. Siebritz | M19: 355065 | N19: 6177630 | O19: ND | P19: ND | Q19: 238 | R19: 2 | S19: 6 | T19: =IF(OR(R19="ND",R19=""),S19,R19) -> 2 | V19: 312 | W19: =IF(OR(U19="ND",U19=""),V19,U19) -> 312 | X19: 3 | Y19: 1.396 | Z19: 110763 | AA19: 1044 | AB19: 8 | AC19: 1988 | AD19: =IF(AC19=0,1000,IF(AC19=9999,"ND",(K19/365.25+1899)-AC19)) -> 8.5578371 | AE19: 6 | AF19: 100 | AG19: 0 | AH19: Sand | AI19: 8 | AJ19: 2470 | AK19: 90 | AL19: 34 | AM19: 13 | AN19: 25.56 | AO19: 1.72 | AP19: 17
A20: 18 | B20: core | C20: Dune Asteraceous Fynbos | D20: 29 | E20: 126.5 | F20: N | G20: IP | H20: NN | I20: NN | J20: NN | K20: 35634 | L20: G. Siebritz | M20: 354834 | N20: 6177804 | O20: ND | P20: ND | Q20: 217 | R20: 2 | S20: 7 | T20: =IF(OR(R20="ND",R20=""),S20,R20) -> 2 | V20: 301 | W20: =IF(OR(U20="ND",U20=""),V20,U20) -> 301 | X20: 3 | Y20: 0.47 | Z20: 109655 | AA20: 1057 | AB20: 8 | AC20: 1988 | AD20: =IF(AC20=0,1000,IF(AC20=9999,"ND",(K20/365.25+1899)-AC20)) -> 8.5605749 | AE20: 4 | AF20: 100 | AG20: 0 | AH20: Sand | AI20: 8 | AJ20: 2460 | AK20: 86 | AL20: 32 | AM20: 19 | AN20: 24.82 | AO20: 2.01 | AP20: 18
A21: 19 | B21: core | C21: Thamnochortus fraternus Restioid Fynbos | D21: 18 | E21: 130 | F21: N | G21: IP | H21: NN | I21: NN | J21: NN | K21: 35636 | L21: G. Siebritz | M21: 355316 | N21: 6177042 | O21: ND | P21: ND | Q21: 340 | R21: 20 | S21: 15 | T21: =IF(OR(R21="ND",R21=""),S21,R21) -> 20 | V21: 296 | W21: =IF(OR(U21="ND",U21=""),V21,U21) -> 296 | X21: 4 | Y21: 0.208 | Z21: 111270 | AA21: 913 | AB21: 8 | AC21: 1990 | AD21: =IF(AC21=0,1000,IF(AC21=9999,"ND",(K21/365.25+1899)-AC21)) -> 6.5660507 | AE21: 1 | AF21: 0 | AG21: 20 | AH21: Sand | AI21: 7.7 | AJ21: 730 | AK21: 130 | AL21: 33 | AM21: 71 | AN21: 33.07 | AO21: 2.63 | AP21: 19
A22: 20 | B22: core | C22: Thamnochortus fraternus Restioid Fynbos | D22: 22 | E22: 114 | F22: N | G22: IP | H22: NN | I22: NN | J22: NN | K22: 35636 | L22: G. Siebritz | M22: 355328 | N22: 6177096 | O22: ND | P22: ND | Q22: 329 | R22: 8 | S22: 19 | T22: =IF(OR(R22="ND",R22=""),S22,R22) -> 8 | V22: 340 | W22: =IF(OR(U22="ND",U22=""),V22,U22) -> 340 | X22: 4 | Y22: 0.637 | Z22: 119625 | AA22: 645 | AB22: ND | AC22: 1990 | AD22: =IF(AC22=0,1000,IF(AC22=9999,"ND",(K22/365.25+1899)-AC22)) -> 6.5660507 | AE22: 2 | AF22: 5 | AG22: 15 | AH22: Sand | AI22: 7.8 | AJ22: 1420 | AK22: 93 | AL22: 19 | AM22: 70 | AN22: 53.2 | AO22: 2.2 | AP22: 20
A23: 21 | B23: core | C23: Thamnochortus fraternus Restioid Fynbos | D23: 25 | E23: 118 | F23: N | G23: IP | H23: NN | I23: NN | J23: NN | K23: 35639 | L23: G. Siebritz | M23: 356254 | N23: 6177547 | O23: ND | P23: ND | Q23: 309 | R23: 5 | S23: 16 | T23: =IF(OR(R23="ND",R23=""),S23,R23) -> 5 | V23: 323 | W23: =IF(OR(U23="ND",U23=""),V23,U23) -> 323 | X23: 6 | Y23: 0.334 | Z23: 115284 | AA23: 589 | AB23: ND | AC23: 1988 | AD23: =IF(AC23=0,1000,IF(AC23=9999,"ND",(K23/365.25+1899)-AC23)) -> 8.5742642 | AE23: 2 | AF23: 0 | AG23: 20 | AH23: Sand | AI23: 7.6 | AJ23: 350 | AK23: 211 | AL23: 74 | AM23: 132 | AN23: 43.57 | AO23: 3.25 | AP23: 21
A24: 22 | B24: core | C24: Thamnochortus fraternus Restioid Fynbos | D24: 15 | E24: 87.5 | F24: N | G24: IP | H24: NN | I24: NN | J24: NN | K24: 35640 | L24: G. Siebritz | M24: 356252 | N24: 6177454 | O24: ND | P24: ND | Q24: 342 | R24: 40 | S24: 21 | T24: =IF(OR(R24="ND",R24=""),S24,R24) -> 40 | V24: 103 | W24: =IF(OR(U24="ND",U24=""),V24,U24) -> 103 | X24: 6 | Y24: 0.464 | Z24: 121175 | AA24: 803 | AB24: ND | AC24: 1990 | AD24: =IF(AC24=0,1000,IF(AC24=9999,"ND",(K24/365.25+1899)-AC24)) -> 6.5770021 | AE24: 1 | AF24: 0 | AG24: 15 | AH24: Sand | AI24: 6.1 | AJ24: 1970 | AK24: 36 | AL24: 13 | AM24: 57 | AN24: 15.18 | AO24: 1.84 | AP24: 22
A25: 23 | B25: core | C25: Thamnochortus fraternus Restioid Fynbos | D25: 19 | E25: 114.5 | F25: N | G25: IP | H25: NN | I25: NN | J25: NN | K25: 35641 | L25: G. Siebritz | M25: 356480 | N25: 6177510 | O25: ND | P25: ND | Q25: 304 | R25: 15 | S25: 12 | T25: =IF(OR(R25="ND",R25=""),S25,R25) -> 15 | V25: 305 | W25: =IF(OR(U25="ND",U25=""),V25,U25) -> 305 | X25: 6 | Y25: 0.02 | Z25: 110807 | AA25: 702 | AB25: 10 | AC25: 1990 | AD25: =IF(AC25=0,1000,IF(AC25=9999,"ND",(K25/365.25+1899)-AC25)) -> 6.5797399 | AE25: 1 | AF25: 0 | AG25: 10 | AH25: Sand | AI25: 6 | AJ25: 1800 | AK25: 87 | AL25: 13 | AM25: 61 | AN25: 11.56 | AO25: 1.66 | AP25: 23
A26: 24 | B26: core | C26: Thamnochortus fraternus Restioid Fynbos | D26: 17 | E26: 102.5 | F26: N | G26: IP | H26: NN | I26: NN | J26: NN | K26: 35641 | L26: G. Siebritz | M26: 356020 | N26: 6177445 | O26: ND | P26: ND | Q26: 340 | R26: 20 | S26: 20 | T26: =IF(OR(R26="ND",R26=""),S26,R26) -> 20 | V26: 30 | W26: =IF(OR(U26="ND",U26=""),V26,U26) -> 30 | X26: 6 | Y26: 0.652 | Z26: 120932 | AA26: 720 | AB26: 8 | AC26: 1990 | AD26: =IF(AC26=0,1000,IF(AC26=9999,"ND",(K26/365.25+1899)-AC26)) -> 6.5797399 | AE26: 1 | AF26: 0 | AG26: 10 | AH26: Sand | AI26: 7.7 | AJ26: 1640 | AK26: 76 | AL26: 22 | AM26: 45 | AN26: 35.51 | AO26: 1.83 | AP26: 24
A27: 25 | B27: core | C27: Dune Asteraceous Fynbos | D27: 40 | E27: 121.5 | F27: N | G27: IP | H27: NN | I27: NN | J27: NN | K27: 35642 | L27: G. Siebritz | M27: 355877 | N27: 6177171 | O27: ND | P27: ND | Q27: 363 | R27: 25 | S27: 18 | T27: =IF(OR(R27="ND",R27=""),S27,R27) -> 25 | V27: 290 | W27: =IF(OR(U27="ND",U27=""),V27,U27) -> 290 | X27: 6 | Y27: 0.336 | Z27: 109447 | AA27: 636 | AB27: 10 | AC27: 1990 | AD27: =IF(AC27=0,1000,IF(AC27=9999,"ND",(K27/365.25+1899)-AC27)) -> 6.5824778 | AE27: 1 | AF27: 0 | AG27: 25 | AH27: Sand | AI27: 7.5 | AJ27: 480 | AK27: 198 | AL27: 130 | AM27: 126 | AN27: 85.85 | AO27: 4.25 | AP27: 25
A28: 26 | B28: core | C28: Neutral Sand Proteoid Fynbos | D28: 20 | E28: 108 | F28: N | G28: IP | H28: NN | I28: NN | J28: NN | K28: 35647 | L28: G. Siebritz | M28: 356209 | N28: 6177045 | O28: ND | P28: ND | Q28: 408 | R28: 2 | S28: 1 | T28: =IF(OR(R28="ND",R28=""),S28,R28) -> 2 | V28: 313 | W28: =IF(OR(U28="ND",U28=""),V28,U28) -> 313 | X28: 6 | Y28: 0.012 | Z28: 111321 | AA28: 1686 | AB28: 8 | AC28: 1990 | AD28: =IF(AC28=0,1000,IF(AC28=9999,"ND",(K28/365.25+1899)-AC28)) -> 6.596167 | AE28: 3 | AF28: 100 | AG28: 0 | AH28: Sand | AI28: 5.8 | AJ28: 3040 | AK28: 6 | AL28: 6 | AM28: 8 | AN28: 6.36 | AO28: 0.61 | AP28: 26
A29: 27 | B29: core | C29: Neutral Sand Proteoid Fynbos | D29: 19 | E29: 109 | F29: N | G29: IP | H29: NN | I29: NN | J29: NN | K29: 35647 | L29: G. Siebritz | M29: 356975 | N29: 6176974 | O29: ND | P29: ND | Q29: 362 | R29: 16 | S29: 12 | T29: =IF(OR(R29="ND",R29=""),S29,R29) -> 16 | V29: 25 | W29: =IF(OR(U29="ND",U29=""),V29,U29) -> 25 | X29: 4 | Y29: 0.546 | Z29: 114271 | AA29: 745 | AB29: ND | AC29: 1990 | AD29: =IF(AC29=0,1000,IF(AC29=9999,"ND",(K29/365.25+1899)-AC29)) -> 6.596167 | AE29: 1 | AF29: 10 | AG29: 10 | AH29: Sand | AI29: 4.8 | AJ29: 4450 | AK29: 28 | AL29: 6 | AM29: 37 | AN29: 2.87 | AO29: 0.5 | AP29: 27
A30: 28 | B30: core | C30: Neutral Sand Proteoid Fynbos | D30: 34 | E30: 115 | F30: N | G30: IP | H30: NN | I30: NN | J30: NN | K30: 35649 | L30: G. Siebritz | M30: 357253 | N30: 6177132 | O30: ND | P30: ND | Q30: 347 | R30: 0 | S30: 8 | T30: =IF(OR(R30="ND",R30=""),S30,R30) -> 0 | V30: 243 | W30: =IF(OR(U30="ND",U30=""),V30,U30) -> 243 | X30: 3 | Y30: 0.829 | Z30: 102683 | AA30: 1084 | AB30: 8 | AC30: 1992 | AD30: =IF(AC30=0,1000,IF(AC30=9999,"ND",(K30/365.25+1899)-AC30)) -> 4.6016427 | AE30: 3 | AF30: 100 | AG30: 0 | AH30: Sand | AI30: 7.8 | AJ30: 3200 | AK30: 108 | AL30: 47 | AM30: 18 | AN30: 64.65 | AO30: 1.02 | AP30: 28
A31: 29 | B31: core | C31: Acid Sand Proteoid Fynbos | D31: 20 | E31: 110 | F31: N | G31: IP | H31: NN | I31: NN | J31: NN | K31: 35649 | L31: G. Siebritz | M31: 357367 | N31: 6176606 | O31: ND | P31: ND | Q31: 380 | R31: 2 | S31: 5 | T31: =IF(OR(R31="ND",R31=""),S31,R31) -> 2 | V31: 205 | W31: =IF(OR(U31="ND",U31=""),V31,U31) -> 205 | X31: 6 | Y31: 0.033 | Z31: 104433 | AA31: 1316 | AB31: ND | AC31: 1990 | AD31: =IF(AC31=0,1000,IF(AC31=9999,"ND",(K31/365.25+1899)-AC31)) -> 6.6016427 | AE31: 1 | AF31: 10 | AG31: 15 | AH31: Sand | AI31: 5.2 | AJ31: 2630 | AK31: 36 | AL31: 5 | AM31: 32 | AN31: 6.05 | AO31: 0.91 | AP31: 29
A32: 30 | B32: core | C32: Acid Sand Proteoid Fynbos | D32: 18 | E32: 110 | F32: N | G32: IP | H32: NN | I32: NN | J32: NN | K32: 35651 | L32: G. Siebritz | M32: 357228 | N32: 6176698 | O32: ND | P32: ND | Q32: 377 | R32: 2 | S32: 5 | T32: =IF(OR(R32="ND",R32=""),S32,R32) -> 2 | V32: 228 | W32: =IF(OR(U32="ND",U32=""),V32,U32) -> 228 | X32: 0 | Y32: 0.252 | Z32: 104829 | AA32: 1279 | AB32: 8 | AC32: 1990 | AD32: =IF(AC32=0,1000,IF(AC32=9999,"ND",(K32/365.25+1899)-AC32)) -> 6.6071184 | AE32: 3 | AF32: 100 | AG32: 0 | AH32: Sand | AI32: 5.3 | AJ32: 2500 | AK32: 6 | AL32: 6 | AM32: 10 | AN32: 4.25 | AO32: 0.91 | AP32: 30
A33: 31 | B33: core | C33: Transitional Proteoid Fynbos | D33: 25 | E33: 124.5 | F33: N | G33: IP | H33: NN | I33: NN | J33: NN | K33: 35653 | L33: G. Siebritz | M33: 357234 | N33: 6176523 | O33: ND | P33: ND | Q33: 364 | R33: 5 | S33: 8 | T33: =IF(OR(R33="ND",R33=""),S33,R33) -> 5 | V33: 203 | W33: =IF(OR(U33="ND",U33=""),V33,U33) -> 203 | X33: 0 | Y33: 1.204 | Z33: 100485 | AA33: 1151 | AB33: 9 | AC33: 1990 | AD33: =IF(AC33=0,1000,IF(AC33=9999,"ND",(K33/365.25+1899)-AC33)) -> 6.6125941 | AE33: 7 | AF33: 15 | AG33: 20 | AH33: Sand | AI33: 5.3 | AJ33: 3100 | AK33: 16 | AL33: 4 | AM33: 27 | AN33: 3.47 | AO33: 0.79 | AP33: 31
A34: 32 | B34: core | C34: True Wetland | D34: 9 | E34: 94.5 | F34: N | G34: IP | H34: NN | I34: NN | J34: NN | K34: 35653 | L34: G. Siebritz | M34: 357063 | N34: 6176436 | O34: ND | P34: ND | Q34: 345 | R34: 0 | S34: 3 | T34: =IF(OR(R34="ND",R34=""),S34,R34) -> 0 | V34: 309 | W34: =IF(OR(U34="ND",U34=""),V34,U34) -> 309 | X34: 3 | Y34: 1.28 | Z34: 109749 | AA34: 1011 | AB34: ND | AC34: 1990 | AD34: =IF(AC34=0,1000,IF(AC34=9999,"ND",(K34/365.25+1899)-AC34)) -> 6.6125941 | AE34: 8 | AF34: 100 | AG34: 0 | AH34: Sand | AI34: 6.3 | AJ34: 1120 | AK34: 20 | AL34: 52 | AM34: 36 | AN34: 20.79 | AO34: 1.87 | AP34: 32
A35: 33 | B35: core | C35: Acid Sand Proteoid Fynbos | D35: 38 | E35: 139.5 | F35: N | G35: IP | H35: NN | I35: NN | J35: NN | K35: 35654 | L35: G. Siebritz | M35: 357694 | N35: 6176143 | O35: ND | P35: ND | Q35: 418 | R35: 22 | S35: 21 | T35: =IF(OR(R35="ND",R35=""),S35,R35) -> 22 | V35: 57 | W35: =IF(OR(U35="ND",U35=""),V35,U35) -> 57 | X35: 6 | Y35: 0.65 | Z35: 121627 | AA35: 557 | AB35: ND | AC35: 1990 | AD35: =IF(AC35=0,1000,IF(AC35=9999,"ND",(K35/365.25+1899)-AC35)) -> 6.615332 | AE35: 1 | AF35: 10 | AG35: 20 | AH35: Sand | AI35: 5.5 | AJ35: 1200 | AK35: 71 | AL35: 12 | AM35: 101 | AN35: 11.79 | AO35: 3.19 | AP35: 33
A36: 34 | B36: core | C36: Acid Sand Fynbos (post-fire regenerating) | D36: 44 | E36: 130.5 | F36: N | G36: IP | H36: NN | I36: NN | J36: NN | K36: 35655 | L36: G. Siebritz | M36: 357409 | N36: 6176060 | O36: ND | P36: ND | Q36: 375 | R36: 22 | S36: 26 | T36: =IF(OR(R36="ND",R36=""),S36,R36) -> 22 | V36: 198 | W36: =IF(OR(U36="ND",U36=""),V36,U36) -> 198 | X36: 0 | Y36: 0.231 | Z36: 74376 | AA36: 937 | AB36: ND | AC36: 1990 | AD36: =IF(AC36=0,1000,IF(AC36=9999,"ND",(K36/365.25+1899)-AC36)) -> 6.6180698 | AE36: 1 | AF36: 12 | AG36: 15 | AH36: Sand | AI36: 5.5 | AJ36: 3200 | AK36: 29 | AL36: 6 | AM36: 52 | AN36: 8.52 | AO36: 1.49 | AP36: 34
A37: 35 | B37: core | C37: Dune Asteraceous Fynbos | D37: 21 | E37: 94.5 | F37: N | G37: IP | H37: NN | I37: NN | J37: NN | K37: 35656 | L37: G. Siebritz | M37: 356622 | N37: 6176374 | O37: ND | P37: ND | Q37: 295 | R37: 30 | S37: 29 | T37: =IF(OR(R37="ND",R37=""),S37,R37) -> 30 | V37: 327 | W37: =IF(OR(U37="ND",U37=""),V37,U37) -> 327 | X37: 4 | Y37: 0.861 | Z37: 115678 | AA37: 285 | AB37: 9 | AC37: 1990 | AD37: =IF(AC37=0,1000,IF(AC37=9999,"ND",(K37/365.25+1899)-AC37)) -> 6.6208077 | AE37: 1 | AF37: 100 | AG37: 25 | AH37: Sand | AI37: 5.9 | AJ37: 1590 | AK37: 46 | AL37: 8 | AM37: 69 | AN37: 9.48 | AO37: 1.56 | AP37: 35
A38: 36 | B38: core | C38: Neutral Sand Proteoid Fynbos | D38: 33 | E38: 122 | F38: N | G38: IP | H38: NN | I38: NN | J38: NN | K38: 35657 | L38: G. Siebritz | M38: 355872 | N38: 6176770 | O38: ND | P38: ND | Q38: 318 | R38: 20 | S38: 13 | T38: =IF(OR(R38="ND",R38=""),S38,R38) -> 20 | V38: 166 | W38: =IF(OR(U38="ND",U38=""),V38,U38) -> 166 | X38: 0 | Y38: 0.612 | Z38: 90981 | AA38: 1292 | AB38: 10 | AC38: 1988 | AD38: =IF(AC38=0,1000,IF(AC38=9999,"ND",(K38/365.25+1899)-AC38)) -> 8.6235455 | AE38: 1 | AF38: 100 | AG38: 0 | AH38: Sand | AI38: 7.8 | AJ38: 1660 | AK38: 87 | AL38: 122 | AM38: 38 | AN38: 66 | AO38: 1.14 | AP38: 36
A39: 37 | B39: core | C39: Transitional Proteoid Fynbos | D39: 40 | E39: 170 | F39: N | G39: IP | H39: NN | I39: NN | J39: NN | K39: 35657 | L39: G. Siebritz | M39: 357598 | N39: 6177427 | O39: ND | P39: ND | Q39: 416 | R39: 12 | S39: 18 | T39: =IF(OR(R39="ND",R39=""),S39,R39) -> 12 | V39: 353 | W39: =IF(OR(U39="ND",U39=""),V39,U39) -> 353 | X39: 6 | Y39: 0.983 | Z39: 121595 | AA39: 787 | AB39: ND | AC39: 1992 | AD39: =IF(AC39=0,1000,IF(AC39=9999,"ND",(K39/365.25+1899)-AC39)) -> 4.6235455 | AE39: 1 | AF39: 100 | AG39: 5 | AH39: Sand | AI39: 6 | AJ39: 1350 | AK39: 20 | AL39: 5 | AM39: 23 | AN39: 8.71 | AO39: 1.19 | AP39: 37
A40: 38 | B40: core | C40: Neutral Sand Proteoid Fynbos | D40: 17 | E40: 103.5 | F40: N | G40: IP | H40: NN | I40: NN | J40: NN | K40: 35660 | L40: G. Siebritz | M40: 357196 | N40: 6177784 | O40: ND | P40: ND | Q40: 358 | R40: 5 | S40: 12 | T40: =IF(OR(R40="ND",R40=""),S40,R40) -> 5 | V40: 348 | W40: =IF(OR(U40="ND",U40=""),V40,U40) -> 348 | X40: 6 | Y40: 0.488 | Z40: 118142 | AA40: 968 | AB40: ND | AC40: 1992 | AD40: =IF(AC40=0,1000,IF(AC40=9999,"ND",(K40/365.25+1899)-AC40)) -> 4.6317591 | AE40: 1 | AF40: 0 | AG40: 10 | AH40: Sand | AI40: 5.1 | AJ40: 1520 | AK40: 60 | AL40: 7 | AM40: 37 | AN40: 5.79 | AO40: 0.8 | AP40: 38
...

Sheet notes
A1: note | B1: description | C1: sampling | E1: coordinates [m UTM WGS84] | G1: altitude [m] | I1: slope | J1: aspect | K1: vegetation age [a] | L1: substrate
C2: date | D2: researcher | E2: x | F2: y | G2: GPS | H2: DEM | I2: DEM | J2: DEM
A3: 1001 | B3: transition 104/106 | C3: 38282 | D3: M. Mergili | E3: 355803 | F3: 6175383 | G3: 231
A4: 1002 | B4: transition 106/108 | C4: 38282 | D4: M. Mergili | E4: 355817 | F4: 6175457 | G4: 243
A5: 1003 | B5: fence 10 m down | C5: 38282 | D5: M. Mergili | E5: 355816 | F5: 6175471 | G5: 234
A6: 1004 | B6: transition to Rooikrans | C6: 38282 | D6: M. Mergili | E6: 355818 | F6: 6175487 | G6: 227
A7: 1005 | B7: transition 61/115 | C7: 38282 | D7: M. Mergili | E7: 356285 | F7: 6175077 | G7: 206
A8: 1006 | B8: transition 61/60 | C8: 38282 | D8: M. Mergili | E8: 356310 | F8: 6175050 | G8: 201
A9: 1007 | B9: ridge | C9: 38282 | D9: M. Mergili | E9: 356291 | F9: 6175098 | G9: 217
A10: 1008 | B10: like releve 61 | C10: 38282 | D10: M. Mergili | E10: 356304 | F10: 6175121 | G10: 218
A11: 1009 | B11: top of ridge | C11: 38282 | D11: M. Mergili | E11: 356300 | F11: 6175132 | G11: 226
A12: 1010 | B12: fence | C12: 38282 | D12: M. Mergili | E12: 356312 | F12: 6175168 | G12: 221
A13: 1011 | B13: transition 112/dune (elev. as 104) | C13: 38282 | D13: M. Mergili | E13: 355760 | F13: 6175345 | G13: ND
A14: 1012 | B14: transition to 134 | C14: 38282 | D14: M. Mergili | E14: 355642 | F14: 6175184 | G14: 273
A15: 1013 | B15: lower edge of forest | C15: 38283 | D15: M. Mergili | E15: 356524 | F15: 6176481 | G15: 242
A16: 1014 | B16: transition 63/f63worepens leuc.con40, asp. Cil 15, othol 10 | C16: 38284 | D16: M. Mergili | E16: 357755 | F16: 6178010 | G16: 299
A17: 1015 | B17: transition 153/154 | C17: 38284 | D17: M. Mergili | E17: 357817 | F17: 6178257 | G17: 267
A18: 1016 | B18: like 63 Leucsp7, Chrys 7 | C18: 38284 | D18: M. Mergili | E18: 357637 | F18: 6177842 | G18: 320
A19: 1017 | B19: transition 58/acid sand | C19: 38284 | D19: M. Mergili | E19: 357542 | F19: 6177532 | G19: 376
A20: 1018 | B20: transition to 69 (lower side) | C20: 38284 | D20: M. Mergili | E20: 357938 | F20: 6177578 | G20: 349
A21: 1019 | B21: end of repens left side | C21: 38284 | D21: M. Mergili | E21: 358142 | F21: 6177330 | G21: 369
A22: 1020 | B22: transition to L. coniferum dominated | C22: 38290 | D22: M. Mergili | E22: 355980 | F22: 6176393 | G22: 310
A23: 1021 | B23: more L. coniferum (45%) | C23: 38290 | D23: M. Mergili | E23: 355842 | F23: 6176241 | G23: 306
A24: 1022 | B24: transition | C24: 38290 | D24: M. Mergili | E24: 355915 | F24: 6176168 | G24: 303
A25: 1023 | B25: transition to 210 | C25: 38290 | D25: M. Mergili | E25: 356069 | F25: 6176185 | G25: 284
... A251: 1249 | B251: transition to grassy (fire?) | C251: 38297 | D251: M. Mergili | E251: 358899 | F251: 6178098 | G251: 363

Sheet sampling
A1: rel. | B1: species | C1: cover | E1: code taxon | F1: code shape | H1: inconsistencies
A2: 1 | B2: Sideroxylon inerme | C2: 85 | E2: Side ine | F2: TREM BLH
A3: 1 | B3: Droguetia iners | C3: 21 | E3: Drog ine | F3: PERL BLS
A4: 1 | B4: Chionanthus foveolatus | C4: 7 | E4: Chio fov | F4: TREM BLH
A5: 1 | B5: Myrsine africana | C5: 4 | E5: Myrs afr | F5: SHRH SLH
A6: 1 | B6: Stipa dregeana | C6: 4 | E6: Stip dre | F6: GRAH GRA
A7: 1 | B7: Cynanchum obtusifolium | C7: 2 | E7: Cyna obt | F7: CLIM BLH
A8: 1 | B8: Zantedeschia aethiopica | C8: 2 | E8: Zant aet | F8: GEOM BLH
A9: 1 | B9: Asparagus aethiopicus | C9: 1 | E9: Aspa aet | F9: CLIM ERI
A10: 1 | B10: Chasmanthe aethiopica | C10: 1 | E10: Chas aet | F10: GEOM BLH
A11: 1 | B11: Ehrharta erecta | C11: 0.5 | E11: Ehrh ere | F11: GRAM GRA
A12: 1 | B12: Kedrostis nana | C12: 0.5 | E12: Kedr nan | F12: CLIM BLS
A13: 1 | B13: Knowltonia vesicatoria | C13: 0.5 | E13: Know ves | F13: PERH BLH
... A2878: 198 | B2878: Helichrysum patulum | C2878: 2 | E2878: Heli pat | F2878: SHRM SLS

Sheet matrix taxon
C1: 1 | D1: 2 | E1: 3 | F1: 4 | G1: 5 | H1: 6 | I1: 7 | J1: 8 | K1: 9 | L1: 10 | M1: 11 | N1: 12 | O1: 13 | P1: 14 | Q1: 15 | R1: 16 | S1: 17 | T1: 18 | U1: 19 | V1: 20 | W1: 21 | X1: 22 | Y1: 23 | Z1: 24 | AA1: 25 | AB1: 26 | AC1: 27 | AD1: 28 | AE1: 29 | AF1: 30 | AG1: 31 | AH1: 32 | AI1: 33 | AJ1: 34 | AK1: 35 | AL1: 36 | AM1: 37 | AN1: 38 | AO1: 39 | AP1: 40 | AQ1: 41 | AR1: 42 | AS1: 43 | AT1: 44 | AU1: 45 | AV1: 46 | AW1: 47 | AX1: 48 | AY1: 49 | AZ1: 50 | BA1: 51 | BB1: 52 | BC1: 53 | BD1: 54 | BE1: 55 | BF1: 56 | BG1: 57 | BH1: 58 | BI1: 59 | BJ1: 60 | BK1: 61 | BL1: 62 | BM1: 63 | BN1: 64 | BO1: 65 | BP1: 66 | BQ1: 67 | BR1: 68 | BS1: 69 | BT1: 70 | BU1: 71
A2: 1 | B2: Side ine | C2: 85 | D2: 95 | E2: 35 | F2: 13 | G2: 10 | AU2: 65 | AZ2: 35 | BA2: 100 | BJ2: 95 | BK2: 80
A3: 2 | B3: Drog ine | C3: 21 | D3: 40 | E3: 12 | F3: 20 | G3: 10 | H3: 4 | J3: 4 | AU3: 8 | AX3: 1 | AZ3: 40 | BA3: 7 | BJ3: 13 | BK3: 45
A4: 3 | B4: Chio fov | C4: 7 | D4: 2 | E4: 8 | F4: 30 | G4: 15 | H4: 10 | I4: 15 | J4: 6 | AU4: 5 | AX4: 10 | AZ4: 8 | BA4: 10 | BJ4: 35 | BK4: 5
A5: 4 | B5: Myrs afr | C5: 4 | D5: 20 | E5: 5 | L5: 1 | AL5: 3 | AU5: 4 | AZ5: 10 | BA5: 2 | BC5: 0.5 | BJ5: 19 | BK5: 4 | BO5: 0.5 | BP5: 1 | BU5: 2
A6: 5 | B6: Stip dre | C6: 4 | D6: 30 | E6: 6 | F6: 1 | G6: 2 | H6: 6 | AX6: 1
A7: 6 | B7: Cyna obt | C7: 2 | D7: 0.5 | E7: 8 | F7: 3 | G7: 6 | H7: 6 | I7: 4 | J7: 3 | AA7: 0.5 | AU7: 3 | AX7: 3 | AZ7: 2 | BA7: 2 | BJ7: 8 | BK7: 2
A8: 7 | B8: Zant aet | C8: 2 | D8: 2 | E8: 2 | J8: 1 | AH8: 2 | BH8: 4 | BI8: 0.5
A9: 8 | B9: Aspa aet | C9: 1 | D9: 4 | E9: 6 | F9: 0.5 | AU9: 4 | AZ9: 6 | BA9: 0.5 | BJ9: 7 | BK9: 1
A10: 9 | B10: Chas aet | C10: 1
A11: 10 | B11: Ehrh ere | C11: 0.5 | D11: 0.5 | E11: 2 | F11: 1 | G11: 0.5 | J11: 0.5 | AU11: 3 | AZ11: 3 | BA11: 20 | BJ11: 2 | BK11: 12
A12: 11 | B12: Kedr nan | C12: 0.5 | E12: 3
A13: 12 | B13: Know ves | C13: 0.5 | M13: 0.5 | N13: 0.5 | O13: 1 | P13: 1 | Z13: 0.5 | AA13: 1 | AI13: 1 | AL13: 1 | AW13: 1 | BC13: 0.5 | BD13: 0.5 | BR13: 0.5 | BU13: 0.5
A14: 13 | B14: Gymn bux | D14: 12 | E14: 4 | F14: 0.5 | G14: 0.5 | H14: 10 | AU14: 8 | AZ14: 0.5 | BJ14: 10
A15: 14 | B15: Eucl rac | D15: 10 | E15: 12 | K15: 2 | L15: 15 | M15: 2 | N15: 15 | R15: 1 | S15: 5 | T15: 12 | AA15: 2 | AY15: 1 | AZ15: 55 | BB15: 0.5 | BC15: 0.5 | BK15: 19 | BM15: 0.5 | BO15: 17 | BP15: 7 | BT15: 4 | BU15: 0.5
A16: 15 | B16: Sola afr | D16: 0.5 | R16: 0.5 | AU16: 3
A17: 16 | B17: Meli rac | E17: 6 | AX17: 1 | AZ17: 0.5 | BJ17: 25
A18: 17 | B18: Rapa mel | F18: 30 | G18: 30 | H18: 20 | I18: 30 | J18: 40 | AX18: 10
A19: 18 | B19: Celt afr | F19: 10 | G19: 15 | J19: 20
A20: 19 | B20: Dios why | F20: 8 | G20: 25 | H20: 15 | I20: 15 | J20: 10 | AX20: 15 | BH20: 0.5
A21: 20 | B21: Aust lan | F21: 7 | G21: 0.5 | J21: 0.5 | AU21: 0.5
A22: 21 | B22: Kigg afr | F22: 6 | G22: 1 | H22: 40 | I22: 30 | AX22: 40 | BH22: 11
A23: 22 | B23: Aspa sca | F23: 4 | G23: 10 | H23: 2 | J23: 2 | AX23: 5
A24: 23 | B24: Aspl adi | F24: 0.5 | G24: 0.5 | I24: 0.5 | BC24: 2 | BD24: 0.5
A25: 24 | B25: Zehn sca | F25: 1 | G25: 2 | H25: 1 | I25: 4 | J25: 0.5 | AU25: 4
A26: 25 | B26: Haem coc | F26: 0.5 | J26: 0.5
A27: 26 | B27: Seca alp | G27: 0.5 | H27: 1 | J27: 8
A28: 27 | B28: Pter den | H28: 6 | AX28: 2 | AY28: 0.5 | BH28: 95
A29: 28 | B29: Rhoi tom | I29: 10 | J29: 30
A30: 29 | B30: Isch ele | K30: 40 | L30: 7 | M30: 30 | N30: 30 | O30: 1 | P30: 11 | R30: 12 | S30: 20 | T30: 15 | U30: 12 | V30: 0.5 | W30: 3 | X30: 4 | Y30: 2 | Z30: 2 | AA30: 2 | AB30: 8 | AC30: 8 | AE30: 0.5 | AI30: 2 | AJ30: 2 | AK30: 10 | AM30: 13 | AR30: 3 | AS30: 0.5 | AT30: 2 | AV30: 3 | AW30: 12 | BD30: 3 | BE30: 1 | BG30: 10 | BM30: 35 | BN30: 1 | BR30: 0.5 | BT30: 10
A31: 30 | B31: Pass vul | K31: 25 | L31: 12 | M31: 15 | N31: 8 | O31: 3 | P31: 10 | Q31: 12 | S31: 20 | T31: 2 | AA31: 0.5 | AC31: 5 | AD31: 3 | AW31: 8 | AY31: 0.5 | BB31: 6 | BE31: 3 | BF31: 16 | BG31: 3 | BL31: 19 | BM31: 3 | BO31: 0.5 | BP31: 9 | BQ31: 0.5 | BR31: 4 | BS31: 23 | BT31: 5
A32: 31 | B32: Pent col | K32: 25 | L32: 8 | M32: 2 | O32: 12 | P32: 2 | R32: 6 | S32: 0.5 | U32: 1 | V32: 3 | AA32: 1 | AD32: 2 | AI32: 2 | AP32: 1 | AQ32: 1 | AT32: 2
A33: 32 | B33: Tetr cus | K33: 20 | M33: 0.5 | S33: 0.5 | U33: 0.5 | V33: 3 | W33: 6 | Y33: 2 | AA33: 4 | AC33: 4 | AD33: 6 | AE33: 2 | AG33: 4 | AJ33: 2 | AK33: 6 | AL33: 3 | AM33: 2 | AN33: 0.5 | AR33: 2 | AW33: 7 | AY33: 8 | BC33: 0.5 | BD33: 30 | BG33: 4 | BM33: 2 | BT33: 15 | BU33: 0.5
A34: 33 | B34: Cass cil | K34: 10 | M34: 1 | N34: 10 | T34: 2 | U34: 1 | AD34: 2 | AL34: 3 | AW34: 6 | BF34: 18 | BI34: 0.5 | BL34: 1 | BP34: 14 | BS34: 1 | BT34: 4
A35: 34 | B35: Meta mur | K35: 8 | L35: 1 | M35: 10 | N35: 15 | O35: 1 | P35: 7 | R35: 0.5 | S35: 20 | T35: 20 | V35: 2 | W35: 6 | Y35: 4 | AA35: 2 | AB35: 25 | AC35: 20 | AD35: 6 | AG35: 0.5 | AK35: 8 | AL35: 4 | AN35: 8 | AT35: 1 | AV35: 3 | AW35: 20 | AY35: 6 | BB35: 20 | BE35: 2 | BG35: 0.5 | BM35: 2 | BT35: 16
A36: 35 | B36: Mura sal | K36: 8 | L36: 0.5 | M36: 2 | O36: 6 | P36: 1 | Q36: 1 | R36: 0.5 | S36: 14 | AD36: 2 | AF36: 2 | AT36: 2 | AV36: 3
A37: 36 | B37: Clut pol | K37: 7 | AD37: 1 | AL37: 2 | AO37: 2 | AP37: 3 | AQ37: 2 | AR37: 1 | AS37: 1 | BD37: 4
A38: 37 | B38: Herm jou | K38: 6 | L38: 5 | M38: 0.5 | N38: 2 | O38: 0.5 | P38: 1 | R38: 4 | S38: 1 | T38: 0.5 | U38: 1 | W38: 0.5 | Z38: 0.5 | AA38: 4 | AB38: 0.5 | AK38: 4 | AM38: 2 | AO38: 0.5 | AV38: 1 | AW38: 4 | BS38: 1
A39: 38 | B39: Indi bra | K39: 5 | L39: 5 | M39: 8 | N39: 12 | O39: 6 | Q39: 2 | R39: 1 | S39: 2 | T39: 7 | U39: 12 | V39: 15 | W39: 25 | X39: 8 | AA39: 3 | AD39: 10 | AE39: 3 | AK39: 2 | AL39: 3 | AM39: 2 | AN39: 15 | AR39: 1 | AS39: 3 | AT39: 1 | AY39: 0.5 | BB39: 14 | BC39: 14 | BD39: 8 | BG39: 6 | BN39: 16 | BR39: 0.5 | BU39: 10
A40: 39 | B40: Meta bre | K40: 5 | M40: 5 | R40: 1 | S40: 8 | T40: 10 | W40: 2 | Y40: 2 | AC40: 5 | AD40: 3 | AE40: 0.5 | AI40: 8 | AJ40: 8 | AK40: 3 | AS40: 0.5 | AW40: 8 | AY40: 3 | BE40: 3 | BM40: 1 | BN40: 0.5 | BR40: 3 | BT40: 0.5 | BU40: 1
...

Sheet matrix shape
C1: 1 | D1: 2 | E1: 3 | F1: 4 | G1: 5 | H1: 6 | I1: 7 | J1: 8 | K1: 9 | L1: 10 | M1: 11 | N1: 12 | O1: 13 | P1: 14 | Q1: 15 | R1: 16 | S1: 17 | T1: 18 | U1: 19 | V1: 20 | W1: 21 | X1: 22 | Y1: 23 | Z1: 24 | AA1: 25 | AB1: 26 | AC1: 27 | AD1: 28 | AE1: 29 | AF1: 30 | AG1: 31 | AH1: 32 | AI1: 33 | AJ1: 34 | AK1: 35 | AL1: 36 | AM1: 37 | AN1: 38 | AO1: 39 | AP1: 40 | AQ1: 41 | AR1: 42 | AS1: 43 | AT1: 44 | AU1: 45 | AV1: 46 | AW1: 47 | AX1: 48 | AY1: 49 | AZ1: 50 | BA1: 51 | BB1: 52 | BC1: 53 | BD1: 54 | BE1: 55 | BF1: 56 | BG1: 57 | BH1: 58 | BI1: 59 | BJ1: 60 | BK1: 61 | BL1: 62 | BM1: 63 | BN1: 64 | BO1: 65 | BP1: 66 | BQ1: 67 | BR1: 68 | BS1: 69 | BT1: 70 | BU1: 71
A2: 1 | B2: TREM BLH | C2: 92 | D2: 107 | E2: 55 | F2: 43 | G2: 25 | H2: 10 | I2: 15 | J2: 6 | AU2: 70 | AX2: 10 | AZ2: 98 | BA2: 110 | BJ2: 130 | BK2: 104
A3: 2 | B3: PERL BLS | C3: 21 | D3: 40 | E3: 12 | F3: 20 | G3: 10 | H3: 4 | J3: 4 | AG3: 0.5 | AJ3: 1 | AU3: 8 | AX3: 1 | AY3: 0.5 | AZ3: 40 | BA3: 7 | BJ3: 13 | BK3: 45 | BN3: 0.5 | BR3: 0.5
A4: 3 | B4: SHRH SLH | C4: 4 | D4: 20 | E4: 5 | L4: 3 | O4: 4 | AL4: 3 | AU4: 4 | AZ4: 10 | BA4: 2 | BC4: 0.5 | BJ4: 19 | BK4: 4 | BO4: 1.5 | BP4: 1.5 | BQ4: 3 | BR4: 0.5 | BT4: 1 | BU4: 2
A5: 4 | B5: GRAH GRA | C5: 4 | D5: 30 | E5: 6 | F5: 1 | G5: 2 | H5: 6 | Q5: 55 | S5: 0.5 | W5: 2 | X5: 8 | Y5: 7 | AA5: 10 | AH5: 5 | AJ5: 2 | AK5: 5 | AR5: 10 | AS5: 10 | AT5: 25 | AX5: 1 | BH5: 2 | BI5: 0.5 | BN5: 5 | BR5: 17 | BU5: 20
A6: 5 | B6: CLIM BLH | C6: 2 | D6: 0.5 | E6: 8 | F6: 3 | G6: 6 | H6: 6 | I6: 14 | J6: 33 | AA6: 0.5 | AU6: 3 | AX6: 3 | AZ6: 2 | BA6: 2 | BJ6: 8 | BK6: 2
A7: 6 | B7: GEOM BLH | C7: 3 | D7: 2 | E7: 2 | J7: 1 | AH7: 2 | BH7: 4 | BI7: 0.5 | BR7: 1
A8: 7 | B8: CLIM ERI | C8: 1 | D8: 4 | E8: 6 | F8: 0.5 | AU8: 4 | AZ8: 6 | BA8: 0.5 | BJ8: 7 | BK8: 1
A9: 8 | B9: GRAM GRA | C9: 0.5 | D9: 0.5 | E9: 8 | F9: 1 | G9: 0.5 | J9: 0.5 | K9: 25 | L9: 10 | M9: 2 | O9: 12 | P9: 2 | R9: 36 | S9: 0.5 | U9: 1.5 | V9: 4 | AA9: 5 | AC9: 2 | AD9: 2 | AI9: 16 | AJ9: 12 | AK9: 15 | AL9: 5 | AM9: 15 | AN9: 2 | AP9: 3 | AQ9: 1 | AT9: 2 | AU9: 3 | AV9: 0.5 | AX9: 1 | AZ9: 3.5 | BA9: 20 | BF9: 4 | BG9: 3 | BI9: 19 | BJ9: 27 | BK9: 12 | BL9: 5 | BO9: 20 | BQ9: 7
A10: 9 | B10: CLIM BLS | C10: 0.5 | E10: 3 | F10: 1 | G10: 2.5 | H10: 2 | I10: 4 | J10: 8.5 | AU10: 4 | BJ10: 3 | BK10: 0.5
A11: 10 | B11: PERH BLH | C11: 0.5 | M11: 0.5 | N11: 0.5 | O11: 1 | P11: 1 | Z11: 0.5 | AA11: 1 | AI11: 1 | AL11: 1 | AW11: 1 | BC11: 0.5 | BD11: 0.5 | BR11: 0.5 | BU11: 0.5
A12: 11 | B12: SHRH BLH | D12: 12 | E12: 4 | F12: 8.5 | G12: 25.5 | H12: 25 | I12: 15 | J12: 10 | K12: 4 | L12: 6 | M12: 3 | P12: 9 | R12: 2 | T12: 3 | V12: 1 | W12: 7 | X12: 29 | Y12: 33 | Z12: 55 | AA12: 6 | AB12: 8.5 | AC12: 1 | AD12: 7 | AG12: 12 | AK12: 1 | AL12: 27 | AM12: 4 | AN12: 31 | AO12: 67 | AP12: 2 | AQ12: 1.5 | AR12: 2 | AS12: 2.5 | AT12: 1 | AU12: 11 | AV12: 5 | AW12: 9 | AX12: 15 | AY12: 2 | AZ12: 0.5 | BC12: 8.5 | BD12: 5 | BE12: 30.5 | BF12: 54 | BG12: 0.5 | BH12: 0.5 | BI12: 0.5 | BJ12: 10 | BL12: 45 | BM12: 3 | BN12: 1 | BO12: 2.5 | BP12: 30.5 | BR12: 2 | BS12: 22 | BT12: 18 | BU12: 5
A13: 12 | B13: SHRH BLS | D13: 0.5 | R13: 0.5 | AU13: 3 | BH13: 0.5 | BI13: 8
A14: 13 | B14: TREH BLH | F14: 30 | G14: 30 | H14: 20 | I14: 30 | J14: 40 | AX14: 10
A15: 14 | B15: TREH BLS | F15: 16 | G15: 16 | H15: 40 | I15: 30 | J15: 20 | AX15: 40 | BH15: 11
